{"content": {"suites": {"0": {"status": {"total_pass": 0, "total_skip": 0, "total_xpass": 0, "total_xfail": 0, "total_rerun": 0, "total_fail": 4, "total_error": 0}, "tests": {"0": {"status": "FAIL", "message": "   sqlite3.OperationalError: no such table: contexts\n   sqlalchemy.exc.OperationalError: (sqlite3.OperationalError) no such table: contexts\n   [SQL: INSERT INTO contexts (id, type, content, content_hash, context_metadata, created_at, updated_at) VALUES (?, ?, ?, ?, ?, ?, ?)]\n   [parameters: ('c80214c9dcf34b82a6df02bf351a92a2', 'test', 'Test content', '9d9595c5d94fb65b824f56e9999527dba9542481580d69feb89056aabaa0aa87', '{\"test\": \"value\"}', '2025-04-02 12:32:23.138959', '2025-04-02 12:32:23.138959')]\n   (Background on this error at: https://sqlalche.me/e/20/e3q8)\n", "test_name": "test_create_context", "rerun": "0"}, "1": {"status": "FAIL", "message": "   sqlite3.OperationalError: no such table: contexts\n   sqlalchemy.exc.OperationalError: (sqlite3.OperationalError) no such table: contexts\n   [SQL: INSERT INTO contexts (id, type, content, content_hash, context_metadata, created_at, updated_at) VALUES (?, ?, ?, ?, ?, ?, ?)]\n   [parameters: ('86b02174421d48898a844a363d4d30fc', 'test', 'Test content', '9d9595c5d94fb65b824f56e9999527dba9542481580d69feb89056aabaa0aa87', '{\"test\": \"value\"}', '2025-04-02 12:32:24.252759', '2025-04-02 12:32:24.252759')]\n   (Background on this error at: https://sqlalche.me/e/20/e3q8)\n", "test_name": "test_list_contexts", "rerun": "0"}, "2": {"status": "FAIL", "message": "   sqlite3.OperationalError: no such table: contexts\n   sqlalchemy.exc.OperationalError: (sqlite3.OperationalError) no such table: contexts\n   [SQL: INSERT INTO contexts (id, type, content, content_hash, context_metadata, created_at, updated_at) VALUES (?, ?, ?, ?, ?, ?, ?)]\n   [parameters: ('178ad959326f468796c801799bfb66ab', 'test', 'Test content', '9d9595c5d94fb65b824f56e9999527dba9542481580d69feb89056aabaa0aa87', '{\"test\": \"value\"}', '2025-04-02 12:32:25.308271', '2025-04-02 12:32:25.308271')]\n   (Background on this error at: https://sqlalche.me/e/20/e3q8)\n", "test_name": "test_get_context", "rerun": "0"}, "3": {"status": "FAIL", "message": "   sqlite3.OperationalError: no such table: contexts\n   sqlalchemy.exc.OperationalError: (sqlite3.OperationalError) no such table: contexts\n   [SQL: INSERT INTO contexts (id, type, content, content_hash, context_metadata, created_at, updated_at) VALUES (?, ?, ?, ?, ?, ?, ?)]\n   [parameters: ('5ea0db217a3348cd962a6751c91cca81', 'test', 'Test content', '9d9595c5d94fb65b824f56e9999527dba9542481580d69feb89056aabaa0aa87', '{\"test\": \"value\"}', '2025-04-02 12:32:26.142676', '2025-04-02 12:32:26.142676')]\n   (Background on this error at: https://sqlalche.me/e/20/e3q8)\n", "test_name": "test_delete_context", "rerun": "0"}}, "suite_name": "tests/test_context.py"}}}, "date": "April 02, 2025", "start_time": 1743597146.1325433, "total_suite": 1, "status": "FAIL", "status_list": {"pass": "0", "fail": "4", "skip": "0", "error": "0", "xpass": "0", "xfail": "0", "rerun": "0"}, "total_tests": "4"}